[0m18:19:29.326844 [debug] [MainThread]: Sending event: {'category': 'dbt', 'action': 'invocation', 'label': 'start', 'context': [<snowplow_tracker.self_describing_json.SelfDescribingJson object at 0x00000165FFE3D7F0>, <snowplow_tracker.self_describing_json.SelfDescribingJson object at 0x000001658236B5F0>, <snowplow_tracker.self_describing_json.SelfDescribingJson object at 0x00000165FFD9C6E0>]}


============================== 18:19:29.343286 | 3bea2eeb-0250-475f-92d5-f164bd5583e4 ==============================
[0m18:19:29.343286 [info ] [MainThread]: Running with dbt=1.9.4
[0m18:19:29.345284 [debug] [MainThread]: running dbt with arguments {'printer_width': '80', 'indirect_selection': 'eager', 'log_cache_events': 'False', 'write_json': 'True', 'partial_parse': 'True', 'cache_selected_only': 'False', 'warn_error': 'None', 'debug': 'False', 'fail_fast': 'False', 'log_path': 'logs', 'profiles_dir': 'C:\\Users\\Owner\\.dbt', 'version_check': 'True', 'use_colors': 'True', 'use_experimental_parser': 'False', 'empty': 'None', 'quiet': 'False', 'no_print': 'None', 'log_format': 'default', 'invocation_command': 'dbt init analytics_warehouse', 'warn_error_options': 'WarnErrorOptions(include=[], exclude=[])', 'static_parser': 'True', 'target_path': 'None', 'introspect': 'True', 'send_anonymous_usage_stats': 'True'}
[0m18:19:29.491983 [debug] [MainThread]: Starter project path: C:\Users\Owner\AppData\Local\Programs\Python\Python312\Lib\site-packages\dbt\include\starter_project
[0m18:19:29.580273 [info ] [MainThread]: 
Your new dbt project "analytics_warehouse" was created!

For more information on how to configure the profiles.yml file,
please consult the dbt documentation here:

  https://docs.getdbt.com/docs/configure-your-profile

One more thing:

Need help? Don't hesitate to reach out to us via GitHub issues or on Slack:

  https://community.getdbt.com/

Happy modeling!

[0m18:19:29.581292 [info ] [MainThread]: Setting up your profile.
[0m18:19:29.584629 [error] [MainThread]: Encountered an error:
'charmap' codec can't decode byte 0x90 in position 167: character maps to <undefined>
[0m18:19:29.659065 [error] [MainThread]: Traceback (most recent call last):
  File "C:\Users\Owner\AppData\Local\Programs\Python\Python312\Lib\site-packages\dbt\cli\requires.py", line 153, in wrapper
    result, success = func(*args, **kwargs)
                      ^^^^^^^^^^^^^^^^^^^^^
  File "C:\Users\Owner\AppData\Local\Programs\Python\Python312\Lib\site-packages\dbt\cli\requires.py", line 103, in wrapper
    return func(*args, **kwargs)
           ^^^^^^^^^^^^^^^^^^^^^
  File "C:\Users\Owner\AppData\Local\Programs\Python\Python312\Lib\site-packages\dbt\cli\main.py", line 477, in init
    results = task.run()
              ^^^^^^^^^^
  File "C:\Users\Owner\AppData\Local\Programs\Python\Python312\Lib\site-packages\dbt\task\init.py", line 346, in run
    self.setup_profile(profile_name)
  File "C:\Users\Owner\AppData\Local\Programs\Python\Python312\Lib\site-packages\dbt\task\init.py", line 248, in setup_profile
    if not self.check_if_can_write_profile(profile_name=profile_name):
           ^^^^^^^^^^^^^^^^^^^^^^^^^^^^^^^^^^^^^^^^^^^^^^^^^^^^^^^^^^
  File "C:\Users\Owner\AppData\Local\Programs\Python\Python312\Lib\site-packages\dbt\task\init.py", line 209, in check_if_can_write_profile
    profiles = yaml.safe_load(f) or {}
               ^^^^^^^^^^^^^^^^^
  File "C:\Users\Owner\AppData\Local\Programs\Python\Python312\Lib\site-packages\yaml\__init__.py", line 125, in safe_load
    return load(stream, SafeLoader)
           ^^^^^^^^^^^^^^^^^^^^^^^^
  File "C:\Users\Owner\AppData\Local\Programs\Python\Python312\Lib\site-packages\yaml\__init__.py", line 79, in load
    loader = Loader(stream)
             ^^^^^^^^^^^^^^
  File "C:\Users\Owner\AppData\Local\Programs\Python\Python312\Lib\site-packages\yaml\loader.py", line 34, in __init__
    Reader.__init__(self, stream)
  File "C:\Users\Owner\AppData\Local\Programs\Python\Python312\Lib\site-packages\yaml\reader.py", line 85, in __init__
    self.determine_encoding()
  File "C:\Users\Owner\AppData\Local\Programs\Python\Python312\Lib\site-packages\yaml\reader.py", line 124, in determine_encoding
    self.update_raw()
  File "C:\Users\Owner\AppData\Local\Programs\Python\Python312\Lib\site-packages\yaml\reader.py", line 178, in update_raw
    data = self.stream.read(size)
           ^^^^^^^^^^^^^^^^^^^^^^
  File "C:\Users\Owner\AppData\Local\Programs\Python\Python312\Lib\encodings\cp1252.py", line 23, in decode
    return codecs.charmap_decode(input,self.errors,decoding_table)[0]
           ^^^^^^^^^^^^^^^^^^^^^^^^^^^^^^^^^^^^^^^^^^^^^^^^^^^^^^^
UnicodeDecodeError: 'charmap' codec can't decode byte 0x90 in position 167: character maps to <undefined>

[0m18:19:29.661459 [debug] [MainThread]: Command `dbt init` failed at 18:19:29.660076 after 0.63 seconds
[0m18:19:29.661459 [debug] [MainThread]: Sending event: {'category': 'dbt', 'action': 'invocation', 'label': 'end', 'context': [<snowplow_tracker.self_describing_json.SelfDescribingJson object at 0x0000016582A22BA0>, <snowplow_tracker.self_describing_json.SelfDescribingJson object at 0x00000165822DEBD0>, <snowplow_tracker.self_describing_json.SelfDescribingJson object at 0x0000016582E55C40>]}
[0m18:19:29.662471 [debug] [MainThread]: Flushing usage events
[0m18:19:29.964286 [debug] [MainThread]: An error was encountered while trying to flush usage events
[0m18:25:10.001349 [debug] [MainThread]: Sending event: {'category': 'dbt', 'action': 'invocation', 'label': 'start', 'context': [<snowplow_tracker.self_describing_json.SelfDescribingJson object at 0x000002BBA005B620>, <snowplow_tracker.self_describing_json.SelfDescribingJson object at 0x000002BB9D6EB1D0>, <snowplow_tracker.self_describing_json.SelfDescribingJson object at 0x000002BB9F3A1280>]}


============================== 18:25:10.010353 | 26fbea2c-1290-4fae-b94b-7eaef03439f9 ==============================
[0m18:25:10.010353 [info ] [MainThread]: Running with dbt=1.9.4
[0m18:25:10.012351 [debug] [MainThread]: running dbt with arguments {'printer_width': '80', 'indirect_selection': 'eager', 'log_cache_events': 'False', 'write_json': 'True', 'partial_parse': 'True', 'cache_selected_only': 'False', 'profiles_dir': 'C:\\Users\\Owner\\.dbt', 'fail_fast': 'False', 'version_check': 'True', 'log_path': 'logs', 'warn_error': 'None', 'debug': 'False', 'use_colors': 'True', 'use_experimental_parser': 'False', 'no_print': 'None', 'quiet': 'False', 'empty': 'None', 'log_format': 'default', 'introspect': 'True', 'static_parser': 'True', 'warn_error_options': 'WarnErrorOptions(include=[], exclude=[])', 'target_path': 'None', 'invocation_command': 'dbt init analytics_warehouse', 'send_anonymous_usage_stats': 'True'}
[0m18:25:10.092308 [info ] [MainThread]: A project called analytics_warehouse already exists here.
[0m18:25:10.095292 [debug] [MainThread]: Command `dbt init` succeeded at 18:25:10.094301 after 0.79 seconds
[0m18:25:10.095821 [debug] [MainThread]: Sending event: {'category': 'dbt', 'action': 'invocation', 'label': 'end', 'context': [<snowplow_tracker.self_describing_json.SelfDescribingJson object at 0x000002BB9D6EB1D0>, <snowplow_tracker.self_describing_json.SelfDescribingJson object at 0x000002BBA005B620>, <snowplow_tracker.self_describing_json.SelfDescribingJson object at 0x000002BB9FB9CDD0>]}
[0m18:25:10.098348 [debug] [MainThread]: Flushing usage events
[0m18:25:10.377309 [debug] [MainThread]: An error was encountered while trying to flush usage events
